<sdf version="1.7" xmlns:xacro="http://www.ros.org/wiki/xacro">
  <xacro:macro name="inchworm_description" params="x y z rx ry rz fixed idx">
    <model name="inchworm_description_${idx}">
      <xacro:if value="${fixed}">
        <joint name="fixed_to_world" type="fixed">
          <parent>world</parent>
          <child>iw_root_${idx}</child>
        </joint>
      </xacro:if>
      <pose>${x} ${y} ${z} ${rx} ${ry} ${rz}</pose>
      <link name="iw_root_${idx}">
        <inertial>
          <pose>0 0 0 0 -0 0</pose>
          <mass>0.151</mass>
          <inertia>
            <ixx>0.0038554</ixx>
            <ixy>0.0094075</ixy>
            <ixz>0.001709</ixz>
            <iyy>0.004445</iyy>
            <iyz>0.0012246</iyz>
            <izz>0.0025729</izz>
          </inertia>
        </inertial>
        <collision name="iw_root_fixed_joint_lump__iw_foot_bottom_collision">
          <pose>0 0 0.025 0 -0 0</pose>
          <geometry>
            <box>
              <size>0.07 0.07 0.05463</size>
            </box>
          </geometry>
          <surface>
            <contact>
              <ode />
            </contact>
            <friction>
              <ode />
            </friction>
          </surface>
        </collision>
        <visual name="iw_root_fixed_joint_lump__iw_foot_bottom_visual">
          <pose>-0.035 0.0425 0 1.57 -0 0</pose>
          <geometry>
            <mesh>
              <scale>0.001 0.001 0.001</scale>
              <uri>model://inchworm_description/meshes/ee.stl</uri>
            </mesh>
          </geometry>
          <material>
            <script>
              <name>Gazebo/Indigo</name>
              <uri>file://media/materials/scripts/gazebo.material</uri>
            </script>
          </material>
        </visual>
      </link>
      <joint name="iw_ankle_foot_bottom_${idx}" type="revolute">
        <pose relative_to="iw_root_${idx}">0 0 0.109 1.57 -0 0</pose>
        <parent>iw_root_${idx}</parent>
        <child>iw_ankle_bottom_${idx}</child>
        <axis>
          <xyz>0 -1 0</xyz>
          <limit>
            <lower>-3.14</lower>
            <upper>3.14</upper>
            <effort>10</effort>
            <velocity>1</velocity>
          </limit>
          <dynamics>
            <damping>5</damping>
            <friction>0.25</friction>
            <spring_reference>0</spring_reference>
            <spring_stiffness>0</spring_stiffness>
          </dynamics>
        </axis>
        <physics>
          <ode>
            <limit>
              <cfm>0</cfm>
              <erp>0.2</erp>
            </limit>
          </ode>
        </physics>
        <physics>
          <ode>
            <implicit_spring_damper>1</implicit_spring_damper>
          </ode>
        </physics>
      </joint>
      <link name="iw_ankle_bottom_${idx}">
        <pose relative_to="iw_ankle_foot_bottom_${idx}">0 0 0 0 -0 0</pose>
        <inertial>
          <pose>0 0 0 0 -0 0</pose>
          <mass>0.151</mass>
          <inertia>
            <ixx>0.0038554</ixx>
            <ixy>0.0094075</ixy>
            <ixz>0.001709</ixz>
            <iyy>0.004445</iyy>
            <iyz>0.0012246</iyz>
            <izz>0.0025729</izz>
          </inertia>
        </inertial>
        <collision name="iw_ankle_bottom_collision">
          <pose>0 -0.02 0.02 0 -0 0</pose>
          <geometry>
            <box>
              <size>0.045 0.08 0.08</size>
            </box>
          </geometry>
          <surface>
            <contact>
              <ode />
            </contact>
            <friction>
              <ode />
            </friction>
          </surface>
        </collision>
        <visual name="iw_ankle_bottom_visual">
          <pose>0.02 -0.065 0.055 3.14159 3e-06 3.14159</pose>
          <geometry>
            <mesh>
              <scale>0.001 0.001 0.001</scale>
              <uri>model://inchworm_description/meshes/ankle_bottom.stl</uri>
            </mesh>
          </geometry>
          <material>
            <script>
              <name>Gazebo/Indigo</name>
              <uri>file://media/materials/scripts/gazebo.material</uri>
            </script>
          </material>
        </visual>
      </link>
      <joint name="iw_beam_ankle_bottom_${idx}" type="revolute">
        <pose relative_to="iw_ankle_bottom_${idx}">0 0 0.0165 0 -0 1.57</pose>
        <parent>iw_ankle_bottom_${idx}</parent>
        <child>iw_beam_bottom_${idx}</child>
        <axis>
          <xyz>0 0 -1</xyz>
          <limit>
            <lower>-0.785</lower>
            <upper>3.14</upper>
            <effort>10</effort>
            <velocity>1</velocity>
          </limit>
          <dynamics>
            <damping>5</damping>
            <friction>0.25</friction>
            <spring_reference>0</spring_reference>
            <spring_stiffness>0</spring_stiffness>
          </dynamics>
        </axis>
        <physics>
          <ode>
            <limit>
              <cfm>0</cfm>
              <erp>0.2</erp>
            </limit>
          </ode>
        </physics>
        <physics>
          <ode>
            <implicit_spring_damper>1</implicit_spring_damper>
          </ode>
        </physics>
      </joint>
      <link name="iw_beam_bottom_${idx}">
        <pose relative_to="iw_beam_ankle_bottom_${idx}">0 0 0 0 -0 0</pose>
        <inertial>
          <pose>0 0 0 0 -0 0</pose>
          <mass>0.151</mass>
          <inertia>
            <ixx>0.0038554</ixx>
            <ixy>0.0094075</ixy>
            <ixz>0.001709</ixz>
            <iyy>0.004445</iyy>
            <iyz>0.0012246</iyz>
            <izz>0.0025729</izz>
          </inertia>
        </inertial>
        <collision name="iw_beam_bottom_collision">
          <pose>0.0825 0 0.005 0 -0 0</pose>
          <geometry>
            <box>
              <size>0.2 0.05 0.06</size>
            </box>
          </geometry>
          <surface>
            <contact>
              <ode />
            </contact>
            <friction>
              <ode />
            </friction>
          </surface>
        </collision>
        <visual name="iw_beam_bottom_visual">
          <pose>0.185 -0.03 0.03325 3.14159 0.001593 3.14159</pose>
          <geometry>
            <mesh>
              <scale>0.001 0.001 0.001</scale>
              <uri>model://inchworm_description/meshes/beam_bottom.stl</uri>
            </mesh>
          </geometry>
          <material>
            <script>
              <name>Gazebo/Indigo</name>
              <uri>file://media/materials/scripts/gazebo.material</uri>
            </script>
          </material>
        </visual>
      </link>
      <joint name="iw_mid_joint_${idx}" type="revolute">
        <pose relative_to="iw_beam_bottom_${idx}">0.165 0 -0.001 3.14 -0 3.14</pose>
        <parent>iw_beam_bottom_${idx}</parent>
        <child>iw_beam_top_${idx}</child>
        <axis>
          <xyz>0 0 1</xyz>
          <limit>
            <lower>-0.785</lower>
            <upper>3.14</upper>
            <effort>10</effort>
            <velocity>1</velocity>
          </limit>
          <dynamics>
            <damping>5</damping>
            <friction>0.25</friction>
            <spring_reference>0</spring_reference>
            <spring_stiffness>0</spring_stiffness>
          </dynamics>
        </axis>
        <physics>
          <ode>
            <limit>
              <cfm>0</cfm>
              <erp>0.2</erp>
            </limit>
          </ode>
        </physics>
        <physics>
          <ode>
            <implicit_spring_damper>1</implicit_spring_damper>
          </ode>
        </physics>
      </joint>
      <link name="iw_beam_top_${idx}">
        <pose relative_to="iw_mid_joint_${idx}">0 0 0 0 -0 0</pose>
        <inertial>
          <pose>0 0 0 0 -0 0</pose>
          <mass>0.151</mass>
          <inertia>
            <ixx>0.0038554</ixx>
            <ixy>0.0094075</ixy>
            <ixz>0.001709</ixz>
            <iyy>0.004445</iyy>
            <iyz>0.0012246</iyz>
            <izz>0.0025729</izz>
          </inertia>
        </inertial>
        <collision name="iw_beam_top_collision">
          <pose>-0.0825 0 -0.005 0 -0 0</pose>
          <geometry>
            <box>
              <size>0.21 0.05 0.08</size>
            </box>
          </geometry>
          <surface>
            <contact>
              <ode />
            </contact>
            <friction>
              <ode />
            </friction>
          </surface>
        </collision>
        <visual name="iw_beam_top_visual">
          <pose>0.02 0.0575 -0.04325 0 -0 3.14</pose>
          <geometry>
            <mesh>
              <scale>0.001 0.001 0.001</scale>
              <uri>model://inchworm_description/meshes/beam_top.stl</uri>
            </mesh>
          </geometry>
          <material>
            <script>
              <name>Gazebo/Indigo</name>
              <uri>file://media/materials/scripts/gazebo.material</uri>
            </script>
          </material>
        </visual>
      </link>
      <joint name="iw_beam_ankle_top_${idx}" type="revolute">
        <pose relative_to="iw_beam_top_${idx}">-0.165 0 0 3.14159 -0 0</pose>
        <parent>iw_beam_top_${idx}</parent>
        <child>iw_ankle_top_${idx}</child>
        <axis>
          <xyz>0 0 -1</xyz>
          <limit>
            <lower>-0.785</lower>
            <upper>3.14</upper>
            <effort>10</effort>
            <velocity>1</velocity>
          </limit>
          <dynamics>
            <damping>5</damping>
            <friction>0.25</friction>
            <spring_reference>0</spring_reference>
            <spring_stiffness>0</spring_stiffness>
          </dynamics>
        </axis>
        <physics>
          <ode>
            <limit>
              <cfm>0</cfm>
              <erp>0.2</erp>
            </limit>
          </ode>
        </physics>
        <physics>
          <ode>
            <implicit_spring_damper>1</implicit_spring_damper>
          </ode>
        </physics>
      </joint>
      <link name="iw_ankle_top_${idx}">
        <pose relative_to="iw_beam_ankle_top_${idx}">0 0 0 0 -0 0</pose>
        <inertial>
          <pose>0 0 0 0 -0 0</pose>
          <mass>0.151</mass>
          <inertia>
            <ixx>0.0038554</ixx>
            <ixy>0.0094075</ixy>
            <ixz>0.001709</ixz>
            <iyy>0.004445</iyy>
            <iyz>0.0012246</iyz>
            <izz>0.0025729</izz>
          </inertia>
        </inertial>
        <collision name="iw_ankle_top_collision">
          <pose>-0.02 0 0 0 -0 0</pose>
          <geometry>
            <box>
              <size>0.08 0.045 0.08</size>
            </box>
          </geometry>
          <surface>
            <contact>
              <ode />
            </contact>
            <friction>
              <ode />
            </friction>
          </surface>
        </collision>
        <visual name="iw_ankle_top_visual">
          <pose>-0.065 -0.02 0.05 3.14 0 1.57</pose>
          <geometry>
            <mesh>
              <scale>0.001 0.001 0.001</scale>
              <uri>model://inchworm_description/meshes/ankle_top.stl</uri>
            </mesh>
          </geometry>
          <material>
            <script>
              <name>Gazebo/Indigo</name>
              <uri>file://media/materials/scripts/gazebo.material</uri>
            </script>
          </material>
        </visual>
      </link>
      <joint name="iw_ankle_foot_top_${idx}" type="revolute">
        <pose relative_to="iw_ankle_top_${idx}">-0.109 0 -0.008 0 1.57 0</pose>
        <parent>iw_ankle_top_${idx}</parent>
        <child>iw_foot_top_${idx}</child>
        <axis>
          <xyz>0 0 -1</xyz>
          <limit>
            <lower>-3.14</lower>
            <upper>3.14</upper>
            <effort>10</effort>
            <velocity>1</velocity>
          </limit>
          <dynamics>
            <damping>5</damping>
            <friction>0.25</friction>
            <spring_reference>0</spring_reference>
            <spring_stiffness>0</spring_stiffness>
          </dynamics>
        </axis>
        <physics>
          <ode>
            <limit>
              <cfm>0</cfm>
              <erp>0.2</erp>
            </limit>
          </ode>
        </physics>
        <physics>
          <ode>
            <implicit_spring_damper>1</implicit_spring_damper>
          </ode>
        </physics>
      </joint>
      <link name="iw_foot_top_${idx}">
        <pose relative_to="iw_ankle_foot_top_${idx}">0 0 0 0 -0 0</pose>
        <inertial>
          <pose>0 0 0 0 -0 0</pose>
          <mass>0.151</mass>
          <inertia>
            <ixx>0.0038554</ixx>
            <ixy>0.0094075</ixy>
            <ixz>0.001709</ixz>
            <iyy>0.004445</iyy>
            <iyz>0.0012246</iyz>
            <izz>0.0025729</izz>
          </inertia>
        </inertial>
        <collision name="iw_foot_top_collision">
          <pose>0 0 0.025 0 -0 0</pose>
          <geometry>
            <box>
              <size>0.07 0.07 0.05463</size>
            </box>
          </geometry>
          <surface>
            <contact>
              <ode />
            </contact>
            <friction>
              <ode />
            </friction>
          </surface>
        </collision>
        <visual name="iw_foot_top_visual">
          <pose>-0.035 0.0425 0 1.57 -0 0</pose>
          <geometry>
            <mesh>
              <scale>0.001 0.001 0.001</scale>
              <uri>model://inchworm_description/meshes/ee.stl</uri>
            </mesh>
          </geometry>
          <material>
            <script>
              <name>Gazebo/Indigo</name>
              <uri>file://media/materials/scripts/gazebo.material</uri>
            </script>
          </material>
        </visual>
      </link>
      <static>0</static>
      <plugin name="gazebo_ros_control" filename="libgazebo_ros_control.so">
        <robotNamespace>/inchworm_${idx}</robotNamespace>
      </plugin>
    </model>
  </xacro:macro>
</sdf>